<?xml version="1.0" ?>
<!-- =================================================================================== -->
<!-- |    This document was autogenerated by xacro from /home/keshav/robot_ws/src/omnit/omnit_description/models/ATR2/model.urdf.xacro | -->
<!-- |    EDITING THIS FILE BY HAND IS NOT RECOMMENDED                                 | -->
<!-- =================================================================================== -->
<robot name="atr2">
  <!-- link flat with the ground -->
  <link name="base_footprint"/>
  <!-- robot default link -->
  <joint name="base_link_to_base_footprint" type="fixed">
    <parent link="base_footprint"/>
    <child link="base_link"/>
    <origin rpy="0 0 0" xyz="0 0 0"/>
  </joint>
  <link name="base_link"/>
  <!-- chassis link with simplified collision objects -->
  <joint name="chassis_to_base_link" type="fixed">
    <parent link="base_link"/>
    <child link="chassis"/>
    <origin rpy="0 0 0" xyz="0 0 0.0445"/>
  </joint>
  <link name="chassis">
    <visual>
      <geometry>
        <mesh filename="file:///home/martin/nxtbot_workspace/src/omnit_description/meshes/omnit_v2/base.dae" scale="1 1 1"/>
      </geometry>
    </visual>
    <collision>
      <geometry>
        <mesh filename="file:///home/martin/nxtbot_workspace/src/omnit_description/meshes/omnit_v2/base_collision.dae" scale="1 1 1"/>
      </geometry>
    </collision>
    <inertial>
      <origin rpy="0 0 0" xyz="0 0 0"/>
      <mass value="20"/>
      <inertia ixx="4" ixy="0.0" ixz="0.0" iyy="6" iyz="0.0" izz="9"/>
    </inertial>
  </link>
  <!-- top box link with simplified collision objects -->
  <joint name="top_box_to_chassis" type="fixed">
    <parent link="chassis"/>
    <child link="top_box"/>
    <origin rpy="0 0 0" xyz="0 0 0.161"/>
  </joint>
  <link name="top_box">
    <visual>
      <geometry>
        <mesh filename="file:///home/martin/nxtbot_workspace/src/omnit_description/meshes/omnit_v2/top_box.dae" scale="1 1 1"/>
      </geometry>
    </visual>
    <collision>
      <origin rpy="0 0 0" xyz="0 0 .043"/>
      <geometry>
        <mesh filename="file:///home/martin/nxtbot_workspace/src/omnit_description/meshes/omnit_v2/top_box_collision.dae" scale="1 1 1"/>
      </geometry>
    </collision>
    <inertial>
      <origin rpy="0 0 0" xyz="0 0 0"/>
      <mass value="5"/>
      <inertia ixx="0.5" ixy="0.0" ixz="0.0" iyy="1" iyz="0.0" izz="1.5"/>
    </inertial>
  </link>
  <!-- robot default link -->
  <joint name="driving_frame_to_base_footprint" type="fixed">
    <parent link="base_footprint"/>
    <child link="driving_frame"/>
    <origin rpy="0 0 0" xyz="0 0 0"/>
  </joint>
  <link name="driving_frame"/>
  <!-- virtual lidar link -->
  <joint name="virtual_lidar_frame_to_chassis" type="fixed">
    <parent link="chassis"/>
    <child link="virtual_lidar"/>
    <origin rpy="0 0 0" xyz="0 0 0.18"/>
  </joint>
  <link name="virtual_lidar"/>
  <!-- wheel body, with origin in the middle -->
  <joint name="front_right_wheel_link_joint" type="fixed">
    <origin rpy="-1.5707963267948966 0 0" xyz="0.279 -0.280 0.0811"/>
    <parent link="base_link"/>
    <child link="front_right_wheel_link"/>
    <axis xyz="0 1 0"/>
  </joint>
  <link name="front_right_wheel_link">
    <visual>
      <origin rpy="1.5707963267948966 0 0" xyz="0 0 0"/>
      <geometry>
        <mesh filename="file:///home/martin/nxtbot_workspace/src/omnit_description/meshes/omnit_v2/wheel.dae" scale="1 1 1"/>
      </geometry>
    </visual>
    <collision>
      <geometry>
        <cylinder length="0.084" radius="0.084"/>
      </geometry>
      <surface>
        <contact>
          <ode>
            <kp>1e15</kp>
            <kd>1e13</kd>
          </ode>
        </contact>
        <friction>
          <ode>
            <mu>1e15</mu>
            <mu2>1e15</mu2>
            <slip1>0</slip1>
            <slip2>0</slip2>
          </ode>
        </friction>
      </surface>
    </collision>
  </link>
  <!-- wheel body, with origin in the middle -->
  <joint name="front_left_wheel_link_joint" type="fixed">
    <origin rpy="1.5707963267948966 0 0" xyz="0.279 0.280 0.0811"/>
    <parent link="base_link"/>
    <child link="front_left_wheel_link"/>
    <axis xyz="0 1 0"/>
  </joint>
  <link name="front_left_wheel_link">
    <visual>
      <origin rpy="1.5707963267948966 0 0" xyz="0 0 0"/>
      <geometry>
        <mesh filename="file:///home/martin/nxtbot_workspace/src/omnit_description/meshes/omnit_v2/wheel.dae" scale="-1 1 1"/>
      </geometry>
    </visual>
    <collision>
      <geometry>
        <cylinder length="0.084" radius="0.084"/>
      </geometry>
      <surface>
        <contact>
          <ode>
            <kp>1e15</kp>
            <kd>1e13</kd>
          </ode>
        </contact>
        <friction>
          <ode>
            <mu>1e15</mu>
            <mu2>1e15</mu2>
            <slip1>0</slip1>
            <slip2>0</slip2>
          </ode>
        </friction>
      </surface>
    </collision>
  </link>
  <!-- wheel body, with origin in the middle -->
  <joint name="rear_right_wheel_link_joint" type="fixed">
    <origin rpy="-1.5707963267948966 0 0" xyz="-0.279 -0.280 0.0811"/>
    <parent link="base_link"/>
    <child link="rear_right_wheel_link"/>
    <axis xyz="0 1 0"/>
  </joint>
  <link name="rear_right_wheel_link">
    <visual>
      <origin rpy="1.5707963267948966 0 0" xyz="0 0 0"/>
      <geometry>
        <mesh filename="file:///home/martin/nxtbot_workspace/src/omnit_description/meshes/omnit_v2/wheel.dae" scale="1 1 1"/>
      </geometry>
    </visual>
    <collision>
      <geometry>
        <cylinder length="0.084" radius="0.084"/>
      </geometry>
      <surface>
        <contact>
          <ode>
            <kp>1e15</kp>
            <kd>1e13</kd>
          </ode>
        </contact>
        <friction>
          <ode>
            <mu>1e15</mu>
            <mu2>1e15</mu2>
            <slip1>0</slip1>
            <slip2>0</slip2>
          </ode>
        </friction>
      </surface>
    </collision>
  </link>
  <!-- wheel body, with origin in the middle -->
  <joint name="rear_left_wheel_link_joint" type="fixed">
    <origin rpy="1.5707963267948966 0 0" xyz="-0.279 0.280 0.0811"/>
    <parent link="base_link"/>
    <child link="rear_left_wheel_link"/>
    <axis xyz="0 1 0"/>
  </joint>
  <link name="rear_left_wheel_link">
    <visual>
      <origin rpy="1.5707963267948966 0 0" xyz="0 0 0"/>
      <geometry>
        <mesh filename="file:///home/martin/nxtbot_workspace/src/omnit_description/meshes/omnit_v2/wheel.dae" scale='-1 1 1'/>
      </geometry>
    </visual>
    <collision>
      <geometry>
        <cylinder length="0.084" radius="0.084"/>
      </geometry>
      <surface>
        <contact>
          <ode>
            <kp>1e15</kp>
            <kd>1e13</kd>
          </ode>
        </contact>
        <friction>
          <ode>
            <mu>1e15</mu>
            <mu2>1e15</mu2>
            <slip1>0</slip1>
            <slip2>0</slip2>
          </ode>
        </friction>
      </surface>
    </collision>
  </link>
  <!-- lidar -->
  <joint name="front_lidar_link_joint" type="fixed">
    <origin rpy="0 0 0" xyz="0.370385 0 0.18"/>
    <parent link="chassis"/>
    <child link="front_lidar_link"/>
  </joint>
  <!-- center pose of the lidar link -->
  <link name="front_lidar_link">
    <visual>
      <geometry>
        <cylinder length="0.001" radius="0.001"/>
      </geometry>
    </visual>
    <inertial>
      <origin rpy="0 0 0" xyz="0 0 0"/>
      <mass value="0.001"/>
      <inertia ixx="0.001" ixy="0.0" ixz="0.0" iyy="0.001" iyz="0.0" izz="0.001"/>
    </inertial>
  </link>
  <joint name="front_lidar_sensor_joint" type="fixed">
    <origin rpy="0 0 0" xyz="0.0 0 0.0"/>
    <parent link="front_lidar_link"/>
    <child link="front_lidar_sensor_frame"/>
  </joint>
  <!-- lidar sensor frame -->
  <link name="front_lidar_sensor_frame">
    <visual>
      <geometry>
        <cylinder length="0.001" radius="0.001"/>
      </geometry>
    </visual>
    <inertial>
      <origin rpy="0 0 0" xyz="0 0 0"/>
      <mass value="0.001"/>
      <inertia ixx="0.001" ixy="0.0" ixz="0.0" iyy="0.001" iyz="0.0" izz="0.001"/>
    </inertial>
  </link>
  <gazebo reference="front_lidar_sensor_joint">
    <preserveFixedJoint>true</preserveFixedJoint>
  </gazebo>
  <gazebo reference="front_lidar_sensor_frame">
    <sensor name="front_lidarsensor" type="gpu_ray">
      <visualize>true</visualize>
      <update_rate>15</update_rate>
      <ray>
        <scan>
          <!-- TODO update with correct values when turntable slot is increased. -->
          <horizontal>
            <samples>400</samples>
            <resolution>1</resolution>
            <min_angle>-2.18</min_angle>
            <max_angle>2.18</max_angle>
          </horizontal>
        </scan>
        <range>
          <min>0.06</min>
          <max>25.0</max>
          <resolution>0.02</resolution>
        </range>
        <noise>
          <type>gaussian</type>
          <!-- Noise parameters based on published spec for Hokuyo laserohachieving "+-30mm" accuracy at range < 10m.  A mean of 0.0m and             stddev of 0.01m will put 99.7% of samples within 0.03m of the true             reading. -->
          <mean>0.0</mean>
          <stddev>0.01</stddev>
        </noise>
      </ray>
      <plugin filename="libgazebo_ros_ray_sensor.so" name="front_lidar_ray_sensor">
        <ros>
          <namespace>front_lidar</namespace>
          <remapping>~/out:=scan_raw</remapping>
        </ros>
        <output_type>sensor_msgs/LaserScan</output_type>
        <frame_name>front_lidar_sensor_frame</frame_name>
      </plugin>
    </sensor>
  </gazebo>
  <gazebo>
    <plugin filename="libgazebo_ros_search_reflector.so" name="front_lidar_search_reflector">
      <ros>
        <!-- Add a namespace -->
        <namespace>reflector_tracker</namespace>
        <remapping>reflector_poses:=reflector_poses</remapping>
      </ros>
      <publish_rate>30.0</publish_rate>
      <reflective_base_name>reflective_base</reflective_base_name>
      <frame_id>front_lidar_sensor_frame</frame_id>
      <yaw_restriction>false</yaw_restriction>
    </plugin>
  </gazebo>
  <!-- lidar -->
  <joint name="back_lidar_link_joint" type="fixed">
    <origin rpy="0 0 -3.141592653589793" xyz="-0.370385 0 0.18"/>
    <parent link="chassis"/>
    <child link="back_lidar_link"/>
  </joint>
  <!-- center pose of the lidar link -->
  <link name="back_lidar_link">
    <visual>
      <geometry>
        <cylinder length="0.001" radius="0.001"/>
      </geometry>
    </visual>
    <inertial>
      <origin rpy="0 0 0" xyz="0 0 0"/>
      <mass value="0.001"/>
      <inertia ixx="0.001" ixy="0.0" ixz="0.0" iyy="0.001" iyz="0.0" izz="0.001"/>
    </inertial>
  </link>
  <joint name="back_lidar_sensor_joint" type="fixed">
    <origin rpy="0 0 0" xyz="0.0 0 0.0"/>
    <parent link="back_lidar_link"/>
    <child link="back_lidar_sensor_frame"/>
  </joint>
  <!-- lidar sensor frame -->
  <link name="back_lidar_sensor_frame">
    <visual>
      <geometry>
        <cylinder length="0.001" radius="0.001"/>
      </geometry>
    </visual>
    <inertial>
      <origin rpy="0 0 0" xyz="0 0 0"/>
      <mass value="0.001"/>
      <inertia ixx="0.001" ixy="0.0" ixz="0.0" iyy="0.001" iyz="0.0" izz="0.001"/>
    </inertial>
  </link>
  <gazebo reference="back_lidar_sensor_joint">
    <preserveFixedJoint>true</preserveFixedJoint>
  </gazebo>
  <gazebo reference="back_lidar_sensor_frame">
    <sensor name="back_lidarsensor" type="gpu_ray">
      <visualize>true</visualize>
      <update_rate>15</update_rate>
      <ray>
        <scan>
          <!-- TODO update with correct values when turntable slot is increased. -->
          <horizontal>
            <samples>400</samples>
            <resolution>1</resolution>
            <min_angle>-2.18</min_angle>
            <max_angle>2.18</max_angle>
          </horizontal>
        </scan>
        <range>
          <min>0.06</min>
          <max>25.0</max>
          <resolution>0.02</resolution>
        </range>
        <noise>
          <type>gaussian</type>
          <!-- Noise parameters based on published spec for Hokuyo laserohachieving "+-30mm" accuracy at range < 10m.  A mean of 0.0m and             stddev of 0.01m will put 99.7% of samples within 0.03m of the true             reading. -->
          <mean>0.0</mean>
          <stddev>0.01</stddev>
        </noise>
      </ray>
      <plugin filename="libgazebo_ros_ray_sensor.so" name="back_lidar_ray_sensor">
        <ros>
          <namespace>back_lidar</namespace>
          <remapping>~/out:=scan_raw</remapping>
        </ros>
        <output_type>sensor_msgs/LaserScan</output_type>
        <frame_name>back_lidar_sensor_frame</frame_name>
      </plugin>
    </sensor>
  </gazebo>
  <gazebo>
    <plugin filename="libgazebo_ros_search_reflector.so" name="back_lidar_search_reflector">
      <ros>
        <!-- Add a namespace -->
        <namespace>reflector_tracker</namespace>
        <remapping>reflector_poses:=reflector_poses</remapping>
      </ros>
      <publish_rate>30.0</publish_rate>
      <reflective_base_name>reflective_base</reflective_base_name>
      <frame_id>back_lidar_sensor_frame</frame_id>
      <yaw_restriction>false</yaw_restriction>
    </plugin>
  </gazebo>
  <material name="aluminum">
    <color rgba="0.5 0.5 0.5 1"/>
  </material>
  <material name="plastic">
    <color rgba="0.1 0.1 0.1 1"/>
  </material>
  <!-- camera body, with origin at bottom screw mount -->
  <joint name="stereo_camera_joint" type="fixed">
    <origin rpy="1.5707963267948966 -0.5235987755982988 0" xyz="0.423802368 0.0145 0.308845"/>
    <parent link="base_link"/>
    <child link="stereo_camera_bottom_screw_frame"/>
  </joint>
  <link name="stereo_camera_bottom_screw_frame"/>
  <joint name="stereo_camera_link_joint" type="fixed">
    <origin rpy="0 0 0" xyz="0.011150000000000002 0.0475 0.0145"/>
    <parent link="stereo_camera_bottom_screw_frame"/>
    <child link="stereo_camera_link"/>
  </joint>
  <link name="stereo_camera_link">
    <visual>
      <!-- the mesh origin is at front plate in between the two infrared camera axes -->
      <!-- <origin xyz="${d455_zero_depth_to_glass-d455_cam_depth/2} ${-d455_cam_depth_py} 0" rpy="0 0 0"/> -->
      <origin rpy="1.5707963267948966 0 1.5707963267948966" xyz="0.0046500000000000005 -0.0475 0"/>
      <geometry>
        <!-- <box size="${d455_cam_depth} ${d455_cam_width} ${d455_cam_height}"/> -->
        <mesh filename="file:///opt/ros/humble/share/realsense2_description/meshes/d455.stl" scale="0.001 0.001 0.001"/>
      </geometry>
      <material name="aluminum"/>
    </visual>
    <collision>
      <origin rpy="0 0 0" xyz="-0.00845 -0.0475 0"/>
      <geometry>
        <box size="0.026 0.124 0.029"/>
      </geometry>
    </collision>
    <inertial>
      <!-- The following are not reliable values, and should not be used for modeling -->
      <mass value="0.072"/>
      <origin xyz="0 0 0"/>
      <inertia ixx="0.003881243" ixy="0.0" ixz="0.0" iyy="0.000498940" iyz="0.0" izz="0.003879257"/>
    </inertial>
  </link>
  <!-- camera depth joints and links -->
  <joint name="stereo_camera_depth_joint" type="fixed">
    <origin rpy="0 0 0" xyz="0 0 0"/>
    <parent link="stereo_camera_link"/>
    <child link="stereo_camera_depth_frame"/>
  </joint>
  <link name="stereo_camera_depth_frame"/>
  <joint name="stereo_camera_depth_optical_joint" type="fixed">
    <origin rpy="-1.5707963267948966 0 -1.5707963267948966" xyz="0 0 0"/>
    <parent link="stereo_camera_depth_frame"/>
    <child link="stereo_camera_depth_optical_frame"/>
  </joint>
  <link name="stereo_camera_depth_optical_frame"/>
  <!-- camera left IR joints and links -->
  <joint name="stereo_camera_infra1_joint" type="fixed">
    <origin rpy="0 0 0" xyz="0 0.0 0"/>
    <parent link="stereo_camera_link"/>
    <child link="stereo_camera_infra1_frame"/>
  </joint>
  <link name="stereo_camera_infra1_frame"/>
  <joint name="stereo_camera_infra1_optical_joint" type="fixed">
    <origin rpy="-1.5707963267948966 0 -1.5707963267948966" xyz="0 0 0"/>
    <parent link="stereo_camera_infra1_frame"/>
    <child link="stereo_camera_infra1_optical_frame"/>
  </joint>
  <link name="stereo_camera_infra1_optical_frame"/>
  <!-- camera right IR joints and links -->
  <joint name="stereo_camera_infra2_joint" type="fixed">
    <origin rpy="0 0 0" xyz="0 -0.095 0"/>
    <parent link="stereo_camera_link"/>
    <child link="stereo_camera_infra2_frame"/>
  </joint>
  <link name="stereo_camera_infra2_frame"/>
  <joint name="stereo_camera_infra2_optical_joint" type="fixed">
    <origin rpy="-1.5707963267948966 0 -1.5707963267948966" xyz="0 0 0"/>
    <parent link="stereo_camera_infra2_frame"/>
    <child link="stereo_camera_infra2_optical_frame"/>
  </joint>
  <link name="stereo_camera_infra2_optical_frame"/>
  <!-- camera color joints and links -->
  <joint name="stereo_camera_color_joint" type="fixed">
    <origin rpy="0 0 0" xyz="0 -0.059 0"/>
    <parent link="stereo_camera_link"/>
    <child link="stereo_camera_color_frame"/>
  </joint>
  <link name="stereo_camera_color_frame"/>
  <joint name="stereo_camera_color_optical_joint" type="fixed">
    <origin rpy="-1.5707963267948966 0 -1.5707963267948966" xyz="0 0 0"/>
    <parent link="stereo_camera_color_frame"/>
    <child link="stereo_camera_color_optical_frame"/>
  </joint>
  <link name="stereo_camera_color_optical_frame"/>
  <link name="stereo_camera_accel_frame"/>
  <link name="stereo_camera_accel_optical_frame"/>
  <link name="stereo_camera_gyro_frame"/>
  <link name="stereo_camera_gyro_optical_frame"/>
  <link name="stereo_camera_imu_optical_frame"/>
  <joint name="stereo_camera_accel_joint" type="fixed">
    <origin rpy="0 0 0" xyz="-0.01602 -0.03022 0.0074"/>
    <parent link="stereo_camera_link"/>
    <child link="stereo_camera_accel_frame"/>
  </joint>
  <joint name="stereo_camera_accel_optical_joint" type="fixed">
    <origin rpy="-1.5707963267948966 0 -1.5707963267948966" xyz="0 0 0"/>
    <parent link="stereo_camera_accel_frame"/>
    <child link="stereo_camera_accel_optical_frame"/>
  </joint>
  <joint name="stereo_camera_gyro_joint" type="fixed">
    <origin rpy="0 0 0" xyz="-0.01602 -0.03022 0.0074"/>
    <parent link="stereo_camera_link"/>
    <child link="stereo_camera_gyro_frame"/>
  </joint>
  <joint name="stereo_camera_gyro_optical_joint" type="fixed">
    <origin rpy="-1.5707963267948966 0 -1.5707963267948966" xyz="0 0 0"/>
    <parent link="stereo_camera_gyro_frame"/>
    <child link="stereo_camera_gyro_optical_frame"/>
  </joint>
  <joint name="stereo_camera_imu_optical_joint" type="fixed">
    <origin rpy="0 0 0" xyz="0 0 0"/>
    <parent link="stereo_camera_gyro_optical_frame"/>
    <child link="stereo_camera_imu_optical_frame"/>
  </joint>
  <gazebo reference="stereo_camera_link">
    <self_collide>0</self_collide>
    <enable_wind>0</enable_wind>
    <kinematic>0</kinematic>
    <gravity>1</gravity>
    <!--<mu>1</mu>-->
    <mu2>1</mu2>
    <fdir1>0 0 0</fdir1>
    <!--<slip1>0</slip1>
      <slip2>0</slip2>-->
    <kp>1e+13</kp>
    <kd>1</kd>
    <!--<max_vel>0.01</max_vel>
      <min_depth>0</min_depth>-->
    <sensor name="stereo_cameracolor" type="camera">
      <camera name="stereo_camera">
        <horizontal_fov>1.5707963267948966</horizontal_fov>
        <image>
          <width>1280</width>
          <height>800</height>
          <format>RGB_INT8</format>
        </image>
        <clip>
          <near>0.1</near>
          <far>100</far>
        </clip>
        <noise>
          <type>gaussian</type>
          <mean>0.0</mean>
          <stddev>0.007</stddev>
        </noise>
      </camera>
      <always_on>1</always_on>
      <update_rate>30</update_rate>
      <visualize>1</visualize>
    </sensor>
    <!-- Sim perf: infra1/infra2 streams disabled — only color + depth are
           required. was: always_on=1, update_rate=30. Sensors kept in the SDF
           so the Gazebo sensor tree is consistent; render cost is negligible
           at 1 Hz with always_on off. -->
    <sensor name="stereo_cameraired1" type="camera">
      <camera name="stereo_camera">
        <horizontal_fov>1.5184364492350666</horizontal_fov>
        <image>
          <width>1280</width>
          <height>720</height>
          <format>L_INT8</format>
        </image>
        <clip>
          <near>0.1</near>
          <far>100</far>
        </clip>
        <noise>
          <type>gaussian</type>
          <mean>0.0</mean>
          <stddev>0.05</stddev>
        </noise>
      </camera>
      <always_on>0</always_on>
      <update_rate>1</update_rate>
      <visualize>0</visualize>
    </sensor>
    <sensor name="stereo_cameraired2" type="camera">
      <camera name="stereo_camera">
        <horizontal_fov>1.5184364492350666</horizontal_fov>
        <image>
          <width>1280</width>
          <height>720</height>
          <format>L_INT8</format>
        </image>
        <clip>
          <near>0.1</near>
          <far>100</far>
        </clip>
        <noise>
          <type>gaussian</type>
          <mean>0.0</mean>
          <stddev>0.05</stddev>
        </noise>
      </camera>
      <always_on>0</always_on>
      <update_rate>1</update_rate>
      <visualize>0</visualize>
    </sensor>
    <sensor name="stereo_cameradepth" type="depth">
      <camera name="stereo_camera">
        <horizontal_fov>1.5184364492350666</horizontal_fov>
        <!-- Sim perf: depth resolution was 1280x720; dropped to 848x480
               (native D455 depth resolution) to reduce GPU + pointcloud cost. -->
        <image>
          <width>848</width>
          <height>480</height>
        </image>
        <clip>
          <near>0.1</near>
          <far>100</far>
        </clip>
        <noise>
          <type>gaussian</type>
          <mean>0.0</mean>
          <stddev>0.100</stddev>
        </noise>
      </camera>
      <always_on>1</always_on>
      <!-- Sim perf: was 90; plugin throttles publication to 30 anyway. -->
      <update_rate>30</update_rate>
      <visualize>0</visualize>
    </sensor>
    <sensor name="stereo_cameraimu_gyro" type="imu">
      <always_on>1</always_on>
      <!-- Publish at 100 hz -->
      <update_rate>100</update_rate>
      <imu>
        <angular_velocity>
          <x>
            <noise type="gaussian">
              <mean>0.0</mean>
              <stddev>2e-4</stddev>
              <bias_mean>0.0000075</bias_mean>
              <bias_stddev>0.0000008</bias_stddev>
            </noise>
          </x>
          <y>
            <noise type="gaussian">
              <mean>0.0</mean>
              <stddev>2e-4</stddev>
              <bias_mean>0.0000075</bias_mean>
              <bias_stddev>0.0000008</bias_stddev>
            </noise>
          </y>
          <z>
            <noise type="gaussian">
              <mean>0.0</mean>
              <stddev>2e-4</stddev>
              <bias_mean>0.0000075</bias_mean>
              <bias_stddev>0.0000008</bias_stddev>
            </noise>
          </z>
        </angular_velocity>
        <linear_acceleration>
          <x>
            <noise type="gaussian">
              <mean>0.0</mean>
              <stddev>1.7e-2</stddev>
              <bias_mean>0.1</bias_mean>
              <bias_stddev>0.001</bias_stddev>
            </noise>
          </x>
          <y>
            <noise type="gaussian">
              <mean>0.0</mean>
              <stddev>1.7e-2</stddev>
              <bias_mean>0.1</bias_mean>
              <bias_stddev>0.001</bias_stddev>
            </noise>
          </y>
          <z>
            <noise type="gaussian">
              <mean>0.0</mean>
              <stddev>1.7e-2</stddev>
              <bias_mean>0.1</bias_mean>
              <bias_stddev>0.001</bias_stddev>
            </noise>
          </z>
        </linear_acceleration>
      </imu>
      <plugin filename="libgazebo_ros_imu_sensor.so" name="stereo_camera_gyro_plugin">
        <ros>
          <remapping>~/out:=stereo_camera/gyro/data_raw</remapping>
        </ros>
        <frame_name>stereo_camera_gyro_optical_frame</frame_name>
        <initial_orientation_as_reference>false</initial_orientation_as_reference>
      </plugin>
    </sensor>
    <sensor name="stereo_cameraimu_accel" type="imu">
      <always_on>1</always_on>
      <!-- Publish at 100 hz -->
      <update_rate>100</update_rate>
      <imu>
        <angular_velocity>
          <x>
            <noise type="gaussian">
              <mean>0.0</mean>
              <stddev>2e-4</stddev>
              <bias_mean>0.0000075</bias_mean>
              <bias_stddev>0.0000008</bias_stddev>
            </noise>
          </x>
          <y>
            <noise type="gaussian">
              <mean>0.0</mean>
              <stddev>2e-4</stddev>
              <bias_mean>0.0000075</bias_mean>
              <bias_stddev>0.0000008</bias_stddev>
            </noise>
          </y>
          <z>
            <noise type="gaussian">
              <mean>0.0</mean>
              <stddev>2e-4</stddev>
              <bias_mean>0.0000075</bias_mean>
              <bias_stddev>0.0000008</bias_stddev>
            </noise>
          </z>
        </angular_velocity>
        <linear_acceleration>
          <x>
            <noise type="gaussian">
              <mean>0.0</mean>
              <stddev>1.7e-2</stddev>
              <bias_mean>0.1</bias_mean>
              <bias_stddev>0.001</bias_stddev>
            </noise>
          </x>
          <y>
            <noise type="gaussian">
              <mean>0.0</mean>
              <stddev>1.7e-2</stddev>
              <bias_mean>0.1</bias_mean>
              <bias_stddev>0.001</bias_stddev>
            </noise>
          </y>
          <z>
            <noise type="gaussian">
              <mean>0.0</mean>
              <stddev>1.7e-2</stddev>
              <bias_mean>0.1</bias_mean>
              <bias_stddev>0.001</bias_stddev>
            </noise>
          </z>
        </linear_acceleration>
      </imu>
      <plugin filename="libgazebo_ros_imu_sensor.so" name="stereo_camera_accel_plugin">
        <ros>
          <remapping>~/out:=stereo_camera/accel/data_raw</remapping>
        </ros>
        <frame_name>stereo_camera_accel_optical_frame</frame_name>
        <initial_orientation_as_reference>false</initial_orientation_as_reference>
      </plugin>
    </sensor>
  </gazebo>
  <gazebo>
    <plugin filename="librealsense_gazebo_plugin.so" name="stereo_camera_plugin">
      <prefix>stereo_camera</prefix>
      <depthUpdateRate>30.0</depthUpdateRate>
      <colorUpdateRate>30.0</colorUpdateRate>
      <!-- Sim perf: infrared disabled (was 30.0); infra1/infra2 not required. -->
      <infraredUpdateRate>0.0</infraredUpdateRate>
      <depthTopicName>stereo_camera/depth/image_raw</depthTopicName>
      <depthCameraInfoTopicName>stereo_camera/depth/camera_info</depthCameraInfoTopicName>
      <colorTopicName>stereo_camera/color/image_raw</colorTopicName>
      <colorCameraInfoTopicName>stereo_camera/color/camera_info</colorCameraInfoTopicName>
      <!-- IR topic names kept non-empty (advertiseCamera("") throws and breaks depth_pub_
             setup); actual IR renders are suppressed by always_on=0 on the ired sensors. -->
      <infrared1TopicName>stereo_camera/infra1/image_raw</infrared1TopicName>
      <infrared1CameraInfoTopicName>stereo_camera/infra1/camera_info</infrared1CameraInfoTopicName>
      <infrared2TopicName>stereo_camera/infra2/image_raw</infrared2TopicName>
      <infrared2CameraInfoTopicName>stereo_camera/infra2/camera_info</infrared2CameraInfoTopicName>
      <colorOpticalframeName>stereo_camera_color_optical_frame</colorOpticalframeName>
      <depthOpticalframeName>stereo_camera_depth_optical_frame</depthOpticalframeName>
      <infrared1OpticalframeName>stereo_camera_infra1_optical_frame</infrared1OpticalframeName>
      <infrared2OpticalframeName>stereo_camera_infra2_optical_frame</infrared2OpticalframeName>
      <rangeMinDepth>0.2</rangeMinDepth>
      <rangeMaxDepth>10.0</rangeMaxDepth>
      <pointCloud>False</pointCloud>
      <pointCloudTopicName>stereo_camera/depth/color/points</pointCloudTopicName>
      <pointCloudCutoff>0.25</pointCloudCutoff>
      <pointCloudCutoffMax>9.0</pointCloudCutoffMax>
    </plugin>
  </gazebo>
  <gazebo>
    <!-- position controller -->
    <plugin filename="libgazebo_ros_planar_move.so" name="omnit_planar_mover">
      <ros>
        <!-- Add a namespace -->
        <namespace>/</namespace>
        <!-- Remap the default topic -->
        <!-- use odom safe to test simulation safety -->
        <remapping>cmd_vel:=cmd_vel/safe</remapping>
        <!-- use default odom so we don't need to run robot localization as in simulation odom is perfect -->
        <remapping>odom:=odom</remapping>
      </ros>
      <!-- Set control loop update rate -->
      <update_rate>100</update_rate>
      <!-- Set odom publish rate -->
      <publish_rate>60</publish_rate>
      <!-- Set if odom required -->
      <publish_odom>true</publish_odom>
      <publish_odom_tf>true</publish_odom_tf>
      <!-- Frame IDs -->
      <odometry_frame>odom</odometry_frame>
      <robot_base_frame>base_footprint</robot_base_frame>
      <!-- Set odom covariance -->
      <covariance_x>0.0001</covariance_x>
      <covariance_y>0.0001</covariance_y>
      <covariance_yaw>0.01</covariance_yaw>
    </plugin>
    <!-- battery controller -->
    <plugin filename="libgazebo_ros_battery.so" name="omnit_gz_classic_battery_plugin">
      <ros>
        <!-- Add a namespace -->
        <namespace>/</namespace>
        <!-- Remap the default topic -->
        <remapping>battery_state:=mcu_system/power/battery_state/data</remapping>
      </ros>
      <battery_name>linear_battery</battery_name>
      <!-- In V -->
      <voltage>48</voltage>
      <!-- In percents -->
      <initial_charge>0.95</initial_charge>
      <!-- In Ah -->
      <capacity>42.0</capacity>
      <!-- In W -->
      <charging_power>3000</charging_power>
      <!-- In W -->
      <static_power_load>144</static_power_load>
      <!-- In W/(m/s) -->
      <friction_power_loss>144</friction_power_loss>
      <!-- In m -->
      <charging_station_max_distance>0.25</charging_station_max_distance>
      <charger_model_name_search_term>charger</charger_model_name_search_term>
      <!-- Set if publishing of topic required -->
      <publish_state>true</publish_state>
      <!-- Set publish rate publish rate -->
      <publish_rate>1</publish_rate>
    </plugin>
  </gazebo>
  <!-- turn table base box link -->
  <joint name="turn_table_base_to_chassis" type="fixed">
    <parent link="chassis"/>
    <child link="turn_table_base"/>
    <origin rpy="0 0 0" xyz="0 0 0.331"/>
  </joint>
  <link name="turn_table_base">
    <visual>
      <geometry>
        <mesh filename="file:///home/martin/nxtbot_workspace/src/omnit_description/meshes/omnit_v2/turn_table_base.dae" scale="1 1 1"/>
      </geometry>
    </visual>
    <inertial>
      <origin rpy="0 0 0" xyz="0 0 0"/>
      <mass value="0.001"/>
      <inertia ixx="0.3" ixy="0.0" ixz="0.0" iyy="0.6" iyz="0.0" izz="1"/>
    </inertial>
  </link>
  <!-- turn table base and top, with origin in the middle -->
  <joint name="turn_table_top_link_joint" type="continuous">
    <axis xyz="0 0 1"/>
    <limit effort="5" velocity="0.75"/>
    <origin rpy="0 0 0" xyz="0.0 0.0 0.0536"/>
    <parent link="turn_table_base"/>
    <child link="turn_table_top_link"/>
    <dynamics damping="0.7" friction="0.9"/>
  </joint>
  <gazebo reference="turn_table_top_link_joint">
    <stopCfm>0.000010</stopCfm>
    <stopErp>0.2</stopErp>
    <implicitSpringDamper>true</implicitSpringDamper>
  </gazebo>
  <link name="turn_table_top_link">
    <visual>
      <geometry>
        <mesh filename="file:///home/martin/nxtbot_workspace/src/omnit_description/meshes/omnit_v2/turn_table.dae" scale="1 1 1"/>
      </geometry>
    </visual>
    <!-- cover collision -->
    <collision>
      <geometry>
        <mesh filename="file:///home/martin/nxtbot_workspace/src/omnit_description/meshes/omnit_v2/turn_table_collision.dae" scale="1 1 1"/>
      </geometry>
      <origin rpy="0 0 0" xyz="0 0 0"/>
    </collision>
    <inertial>
      <origin rpy="0 0 0" xyz="0 0 0"/>
      <mass value="0.001"/>
      <inertia ixx="0.5" ixy="0.0" ixz="0.0" iyy="0.8" iyz="0.0" izz="0.1"/>
    </inertial>
  </link>
  <joint name="base_to_imu_front_top_insert" type="fixed">
    <parent link="turn_table_base"/>
    <child link="imu_front_top_insert"/>
    <origin rpy="0 0 0" xyz="0.3647 0.0377 0.0"/>
  </joint>
  <link name="imu_front_top_insert"/>
  <joint name="imu_front_top_insert_to_device" type="fixed">
    <parent link="imu_front_top_insert"/>
    <child link="imu_front_top"/>
    <origin rpy="0 3.14 -1.57" xyz="0.0 0.0 0.005"/>
  </joint>
  <link name="imu_front_top"/>
  <!-- It's not possible to mirror a set of joints, only a mass. That's why we need to have a 'y_scale' variable in our case -->
  <!-- to determine if you're adding the left and right joints. Additionally, the rotation direction of the arms is also different, -->
  <!-- and we also need to consider the links. -->
  <joint name="turn_table_right_gripper_joint" type="revolute">
    <origin rpy="0 0 1.291965" xyz="-0.08 -0.275 0.0471"/>
    <axis xyz="0 0 1"/>
    <limit effort="100" lower="-1.36" upper="-1.36" velocity="1"/>
    <parent link="turn_table_top_link"/>
    <child link="turn_table_right_gripper_dummy"/>
    <dynamics damping="0.0" friction="0.0"/>
  </joint>
  <link name="turn_table_right_gripper_dummy">
    <inertial>
      <origin rpy="0 0 0" xyz="0 0.0 0"/>
      <mass value="0.1"/>
      <inertia ixx="0.1" ixy="0.0" ixz="0.0" iyy="0.1" iyz="0.0" izz="0.1"/>
    </inertial>
  </link>
  <joint name="turn_table_right_gripper_dummy_joint" type="revolute">
    <origin rpy="0 0 -1.291965" xyz="-0.061927 0.21631 0.0"/>
    <axis xyz="0 0 1"/>
    <limit effort="100" lower="1.36" upper="1.36" velocity="1"/>
    <parent link="turn_table_right_gripper_dummy"/>
    <child link="turn_table_right_gripper"/>
    <dynamics damping="0.0" friction="0.0"/>
  </joint>
  <link name="turn_table_right_gripper">
    <visual>
      <origin rpy="0 0 0" xyz="0.397 -0.2035 0"/>
      <geometry>
        <mesh filename="file:///home/martin/nxtbot_workspace/src/omnit_description/meshes/omnit_v2/elbow.dae" scale="1 1 1"/>
      </geometry>
    </visual>
    <inertial>
      <origin rpy="0 0 0" xyz="0 0 0"/>
      <mass value="0.1"/>
      <inertia ixx="0.1" ixy="0.0" ixz="0.0" iyy="0.1" iyz="0.0" izz="0.1"/>
    </inertial>
  </link>
  <joint name="turn_table_right_gripper_attachment_joint" type="fixed">
    <origin rpy="0 0 0" xyz="0.370 -0.2025 0"/>
    <parent link="turn_table_right_gripper"/>
    <child link="turn_table_right_gripper_attachment"/>
  </joint>
  <link name="turn_table_right_gripper_attachment">
    <visual>
      <origin rpy="0 0 0" xyz="0 0 0"/>
      <geometry>
        <!-- TODO: The position needs to be improved -->
        <mesh filename="file:///home/martin/nxtbot_workspace/src/omnit_description/meshes/omnit_v2/gripper_original.dae" scale="1 1 1"/>
      </geometry>
    </visual>
    <inertial>
      <origin rpy="0 0 0" xyz="0 0 0"/>
      <mass value="0.1"/>
      <inertia ixx="0.1" ixy="0.0" ixz="0.0" iyy="0.1" iyz="0.0" izz="0.1"/>
    </inertial>
  </link>
  <joint name="turn_table_right_gripper_pin_joint" type="fixed">
    <origin rpy="0 0 0" xyz="0.10531 -0.0025 0"/>
    <parent link="turn_table_right_gripper_attachment"/>
    <child link="turn_table_right_gripper_pin"/>
  </joint>
  <gazebo reference="turn_table_right_gripper_pin_joint">
    <preserveFixedJoint>true</preserveFixedJoint>
  </gazebo>
  <link name="turn_table_right_gripper_pin">
    <inertial>
      <origin rpy="0 0 0" xyz="0 0 0"/>
      <mass value="0.1"/>
      <inertia ixx="0.1" ixy="0.0" ixz="0.0" iyy="0.1" iyz="0.0" izz="0.1"/>
    </inertial>
  </link>
  <joint name="turn_table_left_gripper_joint" type="revolute">
    <origin rpy="3.141592653589793 0 -1.291965" xyz="-0.08 0.275 0.0471"/>
    <axis xyz="0 0 1"/>
    <limit effort="100" lower="-1.36" upper="-1.36" velocity="1"/>
    <parent link="turn_table_top_link"/>
    <child link="turn_table_left_gripper_dummy"/>
    <dynamics damping="0.0" friction="0.0"/>
  </joint>
  <link name="turn_table_left_gripper_dummy">
    <inertial>
      <origin rpy="0 0 0" xyz="0 0.0 0"/>
      <mass value="0.1"/>
      <inertia ixx="0.1" ixy="0.0" ixz="0.0" iyy="0.1" iyz="0.0" izz="0.1"/>
    </inertial>
  </link>
  <joint name="turn_table_left_gripper_dummy_joint" type="revolute">
    <origin rpy="0 0 -1.291965" xyz="-0.061927 0.21631 0.0"/>
    <axis xyz="0 0 1"/>
    <limit effort="100" lower="1.36" upper="1.36" velocity="1"/>
    <parent link="turn_table_left_gripper_dummy"/>
    <child link="turn_table_left_gripper"/>
    <dynamics damping="0.0" friction="0.0"/>
  </joint>
  <link name="turn_table_left_gripper">
    <visual>
      <origin rpy="0 0 0" xyz="0.397 -0.2035 0"/>
      <geometry>
        <mesh filename="file:///home/martin/nxtbot_workspace/src/omnit_description/meshes/omnit_v2/elbow.dae" scale="1 1 1"/>
      </geometry>
    </visual>
    <inertial>
      <origin rpy="0 0 0" xyz="0 0 0"/>
      <mass value="0.1"/>
      <inertia ixx="0.1" ixy="0.0" ixz="0.0" iyy="0.1" iyz="0.0" izz="0.1"/>
    </inertial>
  </link>
  <joint name="turn_table_left_gripper_attachment_joint" type="fixed">
    <origin rpy="0 0 0" xyz="0.370 -0.2025 0"/>
    <parent link="turn_table_left_gripper"/>
    <child link="turn_table_left_gripper_attachment"/>
  </joint>
  <link name="turn_table_left_gripper_attachment">
    <visual>
      <origin rpy="0 0 0" xyz="0 0 0"/>
      <geometry>
        <!-- TODO: The position needs to be improved -->
        <mesh filename="file:///home/martin/nxtbot_workspace/src/omnit_description/meshes/omnit_v2/gripper_original.dae" scale="1 1 1"/>
      </geometry>
    </visual>
    <inertial>
      <origin rpy="0 0 0" xyz="0 0 0"/>
      <mass value="0.1"/>
      <inertia ixx="0.1" ixy="0.0" ixz="0.0" iyy="0.1" iyz="0.0" izz="0.1"/>
    </inertial>
  </link>
  <joint name="turn_table_left_gripper_pin_joint" type="fixed">
    <origin rpy="0 0 0" xyz="0.10531 -0.0025 0"/>
    <parent link="turn_table_left_gripper_attachment"/>
    <child link="turn_table_left_gripper_pin"/>
  </joint>
  <gazebo reference="turn_table_left_gripper_pin_joint">
    <preserveFixedJoint>true</preserveFixedJoint>
  </gazebo>
  <link name="turn_table_left_gripper_pin">
    <inertial>
      <origin rpy="0 0 0" xyz="0 0 0"/>
      <mass value="0.1"/>
      <inertia ixx="0.1" ixy="0.0" ixz="0.0" iyy="0.1" iyz="0.0" izz="0.1"/>
    </inertial>
  </link>
  <!-- this joint is the one controlled from gripper pin to top link using a node, do not rename without changing the config-->
  <joint name="turn_table_docking_link_to_turn_table" type="prismatic">
    <origin rpy="0 0 0" xyz="0 0 0.05"/>
    <parent link="turn_table_top_link"/>
    <child link="turn_table_docking_link"/>
    <axis xyz="1 0 0"/>
    <!-- The lower and upper values correspond to the value of the joint if the arms are fully extended -->
    <!-- This is done so that Gazebo has it "fixed" and docking works as you expect in simulation -->
    <!-- These limits do not affect the tf ROS side -->
    <limit effort="0.0" lower="0.617" upper="0.617" velocity="0.0"/>
    <dynamics damping="1000000000000.0" friction="1000000000000.0"/>
  </joint>
  <gazebo reference="turn_table_docking_link_to_turn_table">
    <stopCfm>0.01</stopCfm>
    <stopErp>0.8</stopErp>
    <implicitSpringDamper>true</implicitSpringDamper>
    <springStiffness>1000000000000.0</springStiffness>
  </gazebo>
  <link name="turn_table_docking_link">
    <!-- No visual for this one, as it is in the field of view of the camera -->
    <!--       <visual name="${name}_docking_link_visual">
        <geometry>
          <cylinder length="0.01" radius="0.01" />
        </geometry>
      </visual> -->
    <!-- Do not remove inertial and pose as this does effect the plugin loading this link! -->
    <inertial>
      <origin rpy="0 0 0" xyz="0 0 0"/>
      <mass value="0.001"/>
      <inertia ixx="0.001" ixy="0.0" ixz="0.0" iyy="0.001" iyz="0.0" izz="0.001"/>
    </inertial>
  </link>
  <gazebo>
    <plugin filename="libgazebo_ros_turn_table.so" name="turn_table_plugin">
      <ros>
      </ros>
      <!-- DOCKING PARAMETERS -->
      <cart_docking_link>docking_link</cart_docking_link>
      <turn_table_docking_link>turn_table_docking_link</turn_table_docking_link>
      <turn_table_top_link_joint>turn_table_top_link_joint</turn_table_top_link_joint>
      <turn_table_top_link_joint_lower_limit>-6.28</turn_table_top_link_joint_lower_limit>
      <turn_table_top_link_joint_upper_limit>6.28</turn_table_top_link_joint_upper_limit>
      <!-- Range in meters to trigger attachment between cart and omnit -->
      <cart_attaching_range>0.2</cart_attaching_range>
      <!-- Range in meters to trigger attachment between charger and omnit -->
      <charger_attaching_range>0.05</charger_attaching_range>
      <!-- SIMULATION : worst-case time it takes for robot to rotate and align after attaching/docking with cart (in seconds) -->
      <align_duration>11.0</align_duration>
      <!-- Set if publishing of turn_table_joint required -->
      <publish_turn_table_joint>true</publish_turn_table_joint>
      <!-- Refresh rate of distance checking between carts and omnit -->
      <update_rate>5</update_rate>
      <!-- Set turn_table_joint publish rate -->
      <publish_rate>60</publish_rate>
      <!-- POSITION CONTROLLER (/set_position action server) -->
      <!-- saturating P-control with velocity input-->
      <!-- avoid chatter by choosing freq rate high and max_velocity low-->
      <!-- Set turn_table_joint position control rate -->
      <position_control_rate>20</position_control_rate>
      <!-- Set max velocity for position controller in rad/s -->
      <max_velocity>0.75</max_velocity>
      <reset_cart>false</reset_cart>
      <!-- In seconds, delay to not instantaneously respawn cart -->
      <reset_delay>1.0</reset_delay>
      <dts_version>2</dts_version>
      <turn_table_left_gripper_joint>turn_table_left_gripper_joint</turn_table_left_gripper_joint>
      <turn_table_left_gripper_dummy_joint>turn_table_left_gripper_dummy_joint</turn_table_left_gripper_dummy_joint>
      <turn_table_right_gripper_joint>turn_table_right_gripper_joint</turn_table_right_gripper_joint>
      <turn_table_right_gripper_dummy_joint>turn_table_right_gripper_dummy_joint</turn_table_right_gripper_dummy_joint>
    </plugin>
  </gazebo>
</robot>
